---

---

---
# 6.1 구문 오류와 예외

## 6.1.1 오류의 종류

- 오류
	- 구문 오류 : 프로그램 실행 전에 발생하는 오류
	- 예외, 런타임 오류 : 프로그램 실행 중에 발생하는 오류

- 구문 오류
```python
# 프로그램 시작
print("# 프로그램이 시작되었습니다!")

# 구문 오류 발생 코드
print("# 예외를 강제로 발생시켜 볼게요!)

SyntaxError: unterminated string literal (detected at line 1)
```

- 예외
```python
# 프로그램 시작
print("# 프로그램이 시작되었습니다!")

# 예외 발생 코드
list_a[1]

NameError: name 'list_a' is not defined. Did you mean: 'list'?
```

## 6.1.2 기본 예외 처리

- 예외 처리 방법
	- 조건문을 사용하는 방법
	- try 구문을 사용하는 방법

- 조건문으로 예외 처리하기
```python
# 숫자를 입력받는다.
user_input_a = input("정수 입력> ")

# 사용자 입력이 숫자로만 구성되어 있을 때
if user_input_a.isdigit():
	# 숫자로 변환
	number_input_a = int(user_input_a)
	# 출력합니다.
	print("원의 반지름:", number_input_a)
	# 출력합니다.
	print("원의 둘레:", 2 * 3.14 * number_input_a)
	print("원의 넓이:", 3.14 * number_input_a * number_input_a)
else:
	print("정수를 입력하지 않았습니다.")

실행결과
------
정수 입력> 8
원의 반지름: 8
원의 둘레: 50.24
원의 넓이: 200.96

정수 입력> yes!!
정수를 입력하지 않았습니다.
```

- try except 구문
```python
# try except 구문으로 예외를 처리
try:
	# 숫자로 변환
	number_input_a = int(input("정수 입력>")) # 예외 발생 가능
	# 출력
	print("원의 반지름:", number_input_a)
	print("원의 둘레:", 2 * 3.14 * number_input_a)
	print("원의 넓이:", 3.14 * number_input_a * number_input_a)
except:
	print("무언가 잘못되었습니다.") # 예외가 발생했을 때 실행할 구문

실행결과
------
정수 입력> yes!!
정수를 입력하지 않았습니다.
```

- try except 구문과 pass 키워드 조합하기
	- 숫자로 변환되는 것들만 리스트에 넣기
```python
# 변수를 선언
list_input_a = ["52", "273", "32", "스파이", "103"]

# 반복을 적용
list_number = []
for item in list_input_a:
	# 숫자로 변환해서 리스트에 추가
	try:
		float(item)              # 예외가 발생하면 알아서 다음으로 진행은 안되며, except의 내용으로 넘어간다.
		list_number.append(item) # 예외 없이 통과했으면 리스트에 넣는다.
	except:
		pass

# 출력한다.
print("{} 내부에 있는 숫자는".format(list_input_a))
print("{} 입니다.".format(list_number))
```

- try except else 구문
	- try except 구문 뒤에 else 구문을 붙여 사용하면 '예외가 발생하지 않았을 때 실행할 코드'를 지정할 수 있다.
```python
# try except else 구문으로 예외를 처리한다.
try:
	# 숫자로 변환
	number_input_a = int(input("정수 입력> "))
except:
	print("정수를 입력하지 않았습니다.")
else:
	# 출력한다.
	print("원의 반지름:", number_input_a)
	print("원의 둘레:", 2 * 3.14 * number_input_a)
	print("원의 넓이:", 3.14 * number_input_a * number_input_a)

실행결과
------
정수 입력> 7
원의 반지름: 7
원의 둘레: 43.96
원의 넓이: 153.86

정수 입력> yes!!
정수를 입력하지 않았습니다.
```

- finally 구문
	- 예외 처리 구문에서 가장 마지막에 사용할 수 있는 구문
	- 예외가 발생하든 발생하지 않든 무조건 실행할 때 사용하는 코드
```python
# try except 구문으로 예외를 처리
try:
	# 숫자로 변환
	number_input_a = int(input("정수 입력>"))
	# 출력
	print("원의 반지름:", number_input_a)
	print("원의 둘레:", 2 * 3.14 * number_input_a)
	print("원의 넓이:", 3.14 * number_input_a * number_input_a)
except:
	print("정수를 입력해 주세요.")
else:
	print("예외가 발생하지 않았습니다.")
finally:
	print("일단 프로그램이 어떻게든 끝났습니다.")

실행결과
------
정수 입력>273
원의 반지름: 273
원의 둘레: 1714.44
원의 넓이: 234021.06
예외가 발생하지 않았습니다.
일단 프로그램이 어떻게든 끝났습니다.

정수 입력>yes!!
정수를 입력해 주세요.
일단 프로그램이 어떻게든 끝났습니다.
```

- try, except, finally 구문의 조합
	- try 구문은 단독으로 사용할 수 없으며, 반드시 except 구문 또는 finally 구문과 함께 사용해야 한다.
	- else 구문은 반드시 except 구문 뒤에 사용해야 한다.

-  finally에 대한 오해
	- 일반적으로 finally 키워드를 설명하는 예제로 '파일 처리'를 많이 사용한다.
	- 초보자를 위해 쉽게 설명하기 위한 용도로는 좋지만, 실제 finally 구문을 사용하는 것과는 전혀 관련이 없음.

- finally를 잘못 쓴 예제 코드
	- 현재 예제처럼 간단하게 실행되고 끝나는 코드는 프로그램이 끝났을 때 자신이 열었던 파일을 자동으로 모두 닫으니 상관이 없다.
	- 하지만, 이 프로그램이 항상 켜져 있다면 중간 과정에 예외가 발생했을 때 try 구문 중간에 튕겨 파일이 제대로 닫히지 않는 문제가 발생할 수 있다.
```python
# try except 구문 사용
try:
	# 파일을 연다.
	file = open("info.txt", "w")
	# 여러 처리 수행
	# 파일을 닫는다.
	file.close()
except Exception as e:
	print(e)

print("# 파일이 제대로 닫혔는지 확인하기")
print("file.closed:", file.closed)

실행결과
------
# 파일이 제대로 닫혔는지 확인하기
file.closed: True
```

- 파일 처리 중간에 예외 발생
```python
# try except 구문 사용
try:
	# 파일을 연다.
	file = open("info.txt", "w")
	# 여러 가지 처리 수행
	예외.발생해라()
	# 파일 닫기
	file.close()
except Exception as e:
	print(e)

print("# 파일이 제대로 닫혔는지 확인하기")
print("file.closed:", file.closed)

실행결과
------
name '예외' is not defined
# 파일이 제대로 닫혔는지 확인하기
file.closed: False
```

- finally 구문 사용해 파일 닫기
	- 이는 finally 키워드와 관련한 전형적인 예제
```python
# try except 구문을 사용
try:
	# 파일을 연다.
	file = open("info.txt", "w")
	# 여러 가지 처리 수행
	예외.발생해라()
	# 파일 닫기
	file.close()
except Exception as e:
	print(e)
finally:
	# 파일 닫기
	file.close()

실행결과
------
name '예외' is not defined
# 파일이 제대로 닫혔는지 확인하기
file.closed: True
```

- try except 구문 끝난 후 파일 닫기
	- 굳이 finally를 쓸 필요가 없음
```python
# try except 구문 사용
try:
	# 파일을 연다.
	file = open("info.txt", "w")
	# 여러 가지 처리를 수행
	예외.발생해라()
except Exception as e:
	print(e)

# 파일 닫기
file.close()
print("# 파일이 제대로 닫혔는지 확인하기")
print("file.closed:", file.closed)

실행결과
------
name '예외' is not defined
# 파일이 제대로 닫혔는지 확인하기
file.closed: True
```

- try 구문에서 return 키워드를 사용하는 경우
	- 오히려 finally 구문은 반복문 또는 함수 내부에 있을 때 위력을 발휘한다.
	- try 구문 내부에 return 키워드가 있다는 것이 포인트, try 구문 중간에 탈출해도 finally 구문은 무조건 실행됨
```python
# test() 함수를 선언
def test():
	print("test() 함수의 첫 줄입니다.")
	try:
		print("try 구문이 실행되었습니다.")
		return
		print("try 구문의 return 키워드 뒤입니다.")
	except:
		print("except 구문이 실행되었습니다.")
	else:
		print("else 구문이 실행되었습니다.")
	finally:
		print("finally 구문이 실행되었습니다.")
	print("test() 함수의 마지막 줄입니다.")

# test() 함수를 호출합니다.
test()

실행결과
------
test() 함수의 첫 줄입니다.
try 구문이 실행되었습니다.
finally 구문이 실행되었습니다.
```

- finally 키워드 활용
	- 만약 중간에 return 키워드 등으로 함수를 빠져나갈 때마다 close()를 하도록 코드를 작성했다면 코드가 굉장히 복잡해짐
	- 하지만 이렇게 finally 구문에서 close() 함수를 호출하도록 코드를 작성하면 코드가 깔끔해짐
```python
# 함수 호출
def write_text_file(filename, text):
	# try except 구문을 사용
	try:
		# 파일을 연다.
		file = open(filename, "w")
		# 여러 가지 처리를 한다.
		return
		# 파일에 텍스트를 입력한다.
		file.write(text)
	except Exception as e:
		print(e)
	finally:
		# 파일을 닫는다.
		file.close()

write_text_file("test.txt", "안녕하세요!")
```

- 반복문과 함께 사용하는 경우
	- finally 구문은 무조건 실행되므로 반복문에서 break로 빠져나갈 때도 마찬가지로 실행됨
```python
print("프로그램이 시작되었습니다.")

while True:
	try:
		print("try 구문이 실행되었습니다.")
		break
		print("try 구문의 break 키워드입니다.")
	except:
		print("except 구문이 실행되었습니다.")
	finally:
		print("finally 구문이 실행되었습니다.")
	print("while 반복문의 마지막 줄입니다.")
print("프로그램이 종료되었습니다.")

실행결과
------
프로그램이 시작되었습니다.
try 구문이 실행되었습니다.
finally 구문이 실행되었습니다.
프로그램이 종료되었습니다.
```

---
# 6.2 예외 고급

## 6.2.1 예외 객체

- Exception
```python
# try except 구문으로 예외를 처리
try:
	# 숫자로 변환
	number_input_a = int(input("정수 입력> "))

	# 출력
	print("원의 반지름", number_input_a)
	print("원의 둘레", 2 * 3.14 * number_input_a)
	print("원의 넓이", 3.14 * number_input_a * number_input_a)

except Exception as exception:
	# 예외 객체 출력
	print("type(exception):", type(exception))
	print("exception:", exception)

실행결과
------
정수 입력> yes!!
type(exception): <class 'ValueError'>
exception: invalid literal for int() with base 10: 'yes!!'
```

## 6.2.2 예외 구분하기

- 여러 가지 예외가 발생할 수 있는 상황
```python
# 변수 선언
list_number = [52, 273, 32, 72, 100]

# try except 구문으로 예외를 처리
try:
	# 숫자 입력
	number_input = int(input("정수 입력> "))
	# 리스트의 요소 출력
	print("{} 번째 요소: {}".format(number_input, list_number[number_input]))
except Exception as exception:
	# 예외 객체 출력
	print("type(exception):", type(exception))
	print("exception:", exception)

실행결과
------
정수 입력> 2
2 번째 요소: 32


정수 입력> yes!!
type(exception): <class 'ValueError'>
exception: invalid literal for int() with base 10: 'yes!!'

정수 입력> 100
type(exception): <class 'IndexError'>
exception: list index out of range
```

- 예외 구분하기
```python
# 변수를 선언
list_number = [52, 273, 32, 72, 100]

# try number 구문으로 예외를 처리
try:
	# 숫자 입력
	number_input = int(input("정수 입력> "))
	# 리스트의 요소 출력
	print("{}번째 요소: {}".format(number_input, list_number[number_input]))
except ValueError:
	# ValueError가 발생하는 경우
	print("정수를 입력해 주세요!")
except IndexError:
	# IndexError가 발생하는 경우
	print("리스트의 인덱스를 벗어났어요!")

실행결과
------
정수 입력>  yes!!
정수를 입력해 주세요!

정수 입력> 100
리스트의 인덱스를 벗어났어요!
```

- 예외 구문과 예외 객체
```python
# 변수 선언
list_number = [52, 273, 32, 72, 100]

# try except 구문으로 예외를 처리
try:
	# 숫자를 입력
	number_input = int(input("정수 입력> "))
	# 리스트의 요소를 출력
	print("{}번째 요소: {}".format(number_input, list_number[number_input]))
except ValueError as exception:
	# ValueError가 발생하는 경우
	print("정수를 입력해주세요!")
	print("exception:", exception)
except IndexError as exception:
	# IndexError가 발생하는 경우
	print("리스트의 인덱스를 벗어났어요!")
	print("exception:", exception)

실행결과
------
정수 입력> 100
리스트의 인덱스를 벗어났어요!
exception: list index out of range
```

## 6.2.3 모든 예외 잡기

- 예외 처리를 했지만 예외를 못 잡는 경우
	- else 구문처럼 프로그램이 죽지 않게 마지막에는 모든 예외의 부모라고 할 수 있는 Exception을 넣으면 좋음
```python
# 변수 선언
list_number = [52, 273, 32, 72, 100]

# try except 구문으로 예외 처리
try:
	# 숫자 입력
	number_input = int(input("점수 입력> "))
	# 리스트의 요소 출력
	print("{}번째 요소: {}".format(number_input, list_number[number_input]))
	예외.발생해주세요()
except ValueError as exception:
	# ValueError가 발생하는 경우
	print("정수를 입력해 주세요!")
	print(type(exception), exception)
except IndexError as exception:
	# IndexError가 발생하는 경우
	print("리스트의 인덱스를 벗어났어요!")
	print(type(exception), exception)

실행결과
-------
점수 입력> 1
1번째 요소: 273
Traceback (most recent call last):
  File "/Users/yujeongsang/study/BasicCode/YOLO_Dataset/test.py", line 10, in <module>
    예외.발생해주세요()
NameError: name '예외' is not defined
```

- 모든 예외 잡기
```python
# 변수 선언
list_number = [52, 273, 32, 72, 100]

# try except 구문으로 예외 처리
try:
	# 숫자 입력
	number_input = int(input("점수 입력> "))
	# 리스트의 요소 출력
	print("{}번째 요소: {}".format(number_input, list_number[number_input]))
	예외.발생해주세요()
except ValueError as exception:
	# ValueError가 발생하는 경우
	print("정수를 입력해 주세요!")
	print(type(exception), exception)
except IndexError as exception:
	# IndexError가 발생하는 경우
	print("리스트의 인덱스를 벗어났어요!")
	print(type(exception), exception)
except Exception as exception:
	# 이외의 예외가 발생한 경우
	print("미리 파악하지 못한 예외가 발생했습니다.")
	print(type(exception), exception)

실행결과
------
점수 입력> 1
1번째 요소: 273
미리 파악하지 못한 예외가 발생했습니다.
<class 'NameError'> name '예외' is not defined
```

## 6.2.4 raise 구문

- 아직 구현되지 않은 부분에서 강제로 예외를 발생시키기
	- raise 키워드는 예외를 강제로 발생시키는 기능을 함
	- 사용 방법: raise + 예외 이름
	- 출력되는 메시지를 원하는 형태를 만드려면 예외 클래스를 만들어야 함
```python
# 입력 받기
number = input("정수 입력> ")
number = int(number)

# 조건문 사용
if number > 0:
	# 양수일 때: 아직 미구현 상태입니다.
	raise NotImplementError
else:
	# 음수일 때: 아직 미구현 상태입니다.
	raise NotImplementError
```

- Diango 코드에서 finally 찾아보기
```python
def get_geometry_type(self, table_name, geo_col):
	cursor = self.connection.cursor()
	try:
		cursor.execute('DESCRIBE %s' % self.connection.ops.quote_name(table_name))
		for column, typ, null, key, default, extra in cursor.fetchall():
			if column == geo_col:
				field_type = OGRGeomType(typ).django
				field_params = {}
				break
	finally:
		cursor.close()
```

- finally가 없을 경우의 코드
```python
def get_geometry_type(self, table_name, geo_col):
	cursor = self.connection.cursor()
	try:
		cursor.execute('DESCRIBE %s' % self.connection.ops.quote_name(table_name))
		for column, typ, null, key, default, extra in cursor.fetchall():
			if column == geo_col:
				field_type = OGRGeomType(typ).django
				field_params = {}
				# break 전에 닫기
				cursor.close()
				break
	except:
		# 예외가 발생했을 때 닫기
		cursor.close()
	# 정상적으로 끝났을 때 닫기
	cursor.close()
```

- tensorflow raise 사용 예제
```python
raise ValueError(
	'incompatible dtype; specified: {}, inferrerd from {}: {}'.format(
		element_dtype, elements, inferred_dtype))
```

```python
raise ValueError(
	'element shape may not be specified when creating list from tensor'
)
```

```python
raise NotImplementedError('tensor lists only support removing from the end')
```

